Workbook

Sheet Raw
A1: Own a smart phone_Yes-iPhone (iApple/iOS) | B1: Own a smart phone_Yes-Android (Samsung Galaxy, Google Pixel, OnePlus, Motorola, Nokia) | C1: Own a smart phone_Yes, some other smartphone (please provide) | D1: Own a smart phone_No | E1: Smartphone for activity tracking_No | F1: Smartphone for activity tracking_Fitness and workout monitoring (heart rate, step tracking, jogging, etc.) | G1: Smartphone for activity tracking_Health tracking (blood oxygen, heart rhythm, women's health such as ovulation tracking, etc.) | H1: Smartphone for activity tracking_Sleep monitoring (sleep duration, sleep quality, etc.) | I1: Smartphone for activity tracking_Other activity tracking (please describe) | J1: Weekdays smartphone activity tracked | K1: Weekends smartphone activity tracked | L1: Wearable device ownership_None | M1: Wearable device ownership_Fitbit | N1: Wearable device ownership_Apple Watch | O1: Wearable device ownership_Garmin | P1: Wearable device ownership_Samsung | Q1: Wearable device ownership_Other | R1: Reasons for not owning wearable devices_I want one, I just don't have one yet | S1: Reasons for not owning wearable devices_No particular reason | T1: Reasons for not owning wearable devices_Too expensive | U1: Reasons for not owning wearable devices_Too hard to read | V1: Reasons for not owning wearable devices_Don't trust that they work correctly | W1: Reasons for not owning wearable devices_Don't know enough about them | X1: Reasons for not owning wearable devices_Not interested in tracking | Y1: Reasons for not owning wearable devices_Privacy reasons | Z1: Reasons for not owning wearable devices_Some other reason not listed (please provide) | AA1: Wearable device usage by reason_Apps (social media, news, etc.) | AB1: Wearable device usage by reason_Fitness and workout monitoring (heart rate, step tracking, jogging, etc.) | AC1: Wearable device usage by reason_Sleep monitoring (sleep duration, sleep quality, etc.) | AD1: Wearable device usage by reason_Health tracking (blood oxygen, heart rhythm, women's health such as ovulation tracking, etc.) | AE1: Wearable device usage by reason_Phone calls, emails, texting | AF1: Wearable device usage by reason_Music, audiobooks, or podcasts | AG1: Wearable device usage by reason_Navigation (GPS) | AH1: Wearable device usage by reason_Wear for fashion | AI1: Weekdays wearable device worn | AJ1: Weekends wearable device worn | AK1: Time of day wearable device worn | AL1: Highest level of education | AM1: Interest in future research opportunities | AN1: Types of activities comfortable sharing _Health tracking (blood oxygen, heart rhythm, women's health such as ovulation tracking, etc.) | AO1: Types of activities comfortable sharing _Fitness and workout monitoring (heart rate, step tracking, jogging, etc.) | AP1: Types of activities comfortable sharing _Sleep monitoring (sleep duration, sleep quality, etc.) | AQ1: Types of activities comfortable sharing _Self-reported measures from health and fitness apps (mindfulness and mood, water intake, food logs, women's health, etc.) | AR1: Employment Status | AS1: Gender | AT1: Highest level of education_0 | AU1: Race / Ethnicity_Black or African American | AV1: Race / Ethnicity_Asian or Asian American | AW1: Race / Ethnicity_Hispanic | AX1: Race / Ethnicity_White or Caucasian | AY1: Race / Ethnicity - Other | AZ1: generation_age_group
A2: 0 | B2: 1 | C2: 0 | D2: 0 | E2: 1 | F2: 0 | G2: 0 | H2: 0 | I2: 0 | L2: 1 | M2: 0 | N2: 0 | O2: 0 | P2: 0 | Q2: 0 | R2: 0 | S2: 1 | T2: 0 | U2: 0 | V2: 0 | W2: 0 | X2: 0 | Y2: 0 | Z2: 0 | AL2: Graduate degree | AM2: No | AR2: Employed full-time | AS2: Female | AT2: Graduate degree | AU2: 0 | AV2: 0 | AW2: 0 | AX2: 1 | AY2: 0 | AZ2: 42_57
A3: 1 | B3: 0 | C3: 0 | D3: 0 | E3: 0 | F3: 1 | G3: 0 | H3: 0 | I3: 0 | J3: Varies from week to week | K3: Varies from weekend to weekend | L3: 0 | M3: 0 | N3: 1 | O3: 0 | P3: 0 | Q3: 0 | AA3: Secondary reason | AB3: Main reason | AC3: Not a reason | AD3: Secondary reason | AE3: Main reason | AF3: Not a reason | AG3: Not a reason | AH3: Not a reason | AI3: Varies from week to week | AJ3: Varies from weekend to weekend | AK3: Daytime only | AL3: Graduate degree | AM3: Maybe | AN3: Maybe | AO3: Yes | AP3: Maybe | AQ3: Maybe | AR3: Employed full-time | AS3: Female | AT3: Graduate degree | AU3: 0 | AV3: 0 | AW3: 0 | AX3: 1 | AY3: 0 | AZ3: 42_57
A4: 1 | B4: 0 | C4: 0 | D4: 0 | E4: 0 | F4: 1 | G4: 1 | H4: 1 | I4: 0 | J4: All weekdays | K4: Both Saturday and Sunday | L4: 0 | M4: 0 | N4: 1 | O4: 0 | P4: 0 | Q4: 0 | AA4: Not a reason | AB4: Main reason | AC4: Secondary reason | AD4: Secondary reason | AE4: Main reason | AF4: Not a reason | AG4: Not applicable to my device(s) | AH4: Secondary reason | AI4: All weekdays | AJ4: Both Saturday and Sunday | AK4: Daytime only | AL4: Graduate degree | AM4: Yes | AN4: Yes | AO4: Yes | AP4: Maybe | AQ4: Yes | AR4: Employed full-time | AS4: Male | AT4: Graduate degree | AU4: 1 | AV4: 0 | AW4: 0 | AX4: 0 | AY4: 0 | AZ4: 26_41
A5: 1 | B5: 0 | C5: 0 | D5: 0 | E5: 0 | F5: 0 | G5: 0 | H5: 0 | I5: 1 | J5: Varies from week to week | K5: Varies from weekend to weekend | L5: 1 | M5: 0 | N5: 0 | O5: 0 | P5: 0 | Q5: 0 | R5: 0 | S5: 1 | T5: 0 | U5: 0 | V5: 0 | W5: 0 | X5: 0 | Y5: 0 | Z5: 0 | AL5: Some college but no degree | AM5: Yes | AN5: Yes | AO5: Yes | AP5: Yes | AQ5: Maybe | AR5: Retired, not looking for work | AS5: Male | AT5: Some college but no degree | AU5: 1 | AV5: 0 | AW5: 0 | AX5: 0 | AY5: 0 | AZ5: 58_76
A6: 1 | B6: 0 | C6: 0 | D6: 0 | E6: 0 | F6: 1 | G6: 0 | H6: 1 | I6: 0 | J6: All weekdays | K6: Both Saturday and Sunday | L6: 0 | M6: 0 | N6: 1 | O6: 0 | P6: 0 | Q6: 0 | AA6: Not a reason | AB6: Main reason | AC6: Secondary reason | AD6: Secondary reason | AE6: Secondary reason | AF6: Secondary reason | AG6: Secondary reason | AH6: Secondary reason | AI6: All weekdays | AJ6: Both Saturday and Sunday | AK6: Always (day and night) | AL6: Graduate degree | AM6: Maybe | AN6: No | AO6: Yes | AP6: Yes | AQ6: No | AR6: Disabled, not able to work | AS6: Female | AT6: Graduate degree | AU6: 0 | AV6: 0 | AW6: 0 | AX6: 1 | AY6: 0 | AZ6: 58_76
A7: 1 | B7: 0 | C7: 0 | D7: 0 | E7: 0 | F7: 1 | G7: 0 | H7: 0 | I7: 0 | J7: All weekdays | K7: Both Saturday and Sunday | L7: 0 | M7: 1 | N7: 0 | O7: 0 | P7: 0 | Q7: 0 | AA7: Not applicable to my device(s) | AB7: Main reason | AC7: Secondary reason | AD7: Main reason | AE7: Not a reason | AF7: Not applicable to my device(s) | AG7: Not applicable to my device(s) | AH7: Not a reason | AI7: All weekdays | AJ7: Both Saturday and Sunday | AK7: Always (day and night) | AL7: Graduate degree | AM7: Maybe | AN7: No | AO7: Yes | AP7: Yes | AQ7: Maybe | AR7: Retired, not looking for work | AS7: Female | AT7: Graduate degree | AU7: 0 | AV7: 0 | AW7: 0 | AX7: 1 | AY7: 0 | AZ7: 58_76
A8: 0 | B8: 1 | C8: 0 | D8: 0 | E8: 0 | F8: 0 | G8: 0 | H8: 0 | I8: 1 | J8: Varies from week to week | K8: Varies from weekend to weekend | L8: 1 | M8: 0 | N8: 0 | O8: 0 | P8: 0 | Q8: 0 | R8: 0 | S8: 0 | T8: 0 | U8: 0 | V8: 0 | W8: 0 | X8: 0 | Y8: 0 | Z8: 1 | AL8: Some college but no degree | AM8: No | AR8: Disabled, not able to work | AS8: Female | AT8: Some college but no degree | AU8: 0 | AV8: 0 | AW8: 0 | AX8: 1 | AY8: 0 | AZ8: 58_76
A9: 1 | B9: 0 | C9: 0 | D9: 0 | E9: 0 | F9: 1 | G9: 0 | H9: 1 | I9: 0 | J9: All weekdays | K9: Both Saturday and Sunday | L9: 0 | M9: 1 | N9: 0 | O9: 0 | P9: 0 | Q9: 0 | AA9: Not a reason | AB9: Main reason | AC9: Secondary reason | AD9: Not a reason | AE9: Not a reason | AF9: Not a reason | AG9: Not applicable to my device(s) | AH9: Not a reason | AI9: All weekdays | AJ9: Both Saturday and Sunday | AK9: Always (day and night) | AL9: College graduate | AM9: Maybe | AN9: Maybe | AO9: Yes | AP9: Yes | AQ9: No | AR9: Employed part-time | AS9: Female | AT9: College graduate | AU9: 0 | AV9: 0 | AW9: 0 | AX9: 1 | AY9: 0 | AZ9: 58_76
A10: 1 | B10: 0 | C10: 0 | D10: 0 | E10: 1 | F10: 0 | G10: 0 | H10: 0 | I10: 0 | L10: 1 | M10: 0 | N10: 0 | O10: 0 | P10: 0 | Q10: 0 | R10: 1 | S10: 0 | T10: 0 | U10: 0 | V10: 0 | W10: 0 | X10: 0 | Y10: 0 | Z10: 0 | AL10: College graduate | AM10: Yes | AN10: Yes | AO10: Yes | AP10: Yes | AQ10: Maybe | AR10: Employed part-time | AS10: Female | AT10: College graduate | AU10: 0 | AV10: 0 | AW10: 0 | AX10: 1 | AY10: 0 | AZ10: 42_57
A11: 1 | B11: 0 | C11: 0 | D11: 0 | E11: 1 | F11: 0 | G11: 0 | H11: 0 | I11: 0 | L11: 1 | M11: 0 | N11: 0 | O11: 0 | P11: 0 | Q11: 0 | R11: 0 | S11: 0 | T11: 1 | U11: 0 | V11: 0 | W11: 0 | X11: 0 | Y11: 0 | Z11: 0 | AL11: Graduate degree | AM11: Yes | AN11: Yes | AO11: Maybe | AP11: Yes | AQ11: Yes | AR11: Not employed, but looking for work | AS11: Female | AT11: Graduate degree | AU11: 0 | AV11: 1 | AW11: 0 | AX11: 0 | AY11: 0 | AZ11: 42_57
A12: 0 | B12: 1 | C12: 0 | D12: 0 | E12: 0 | F12: 0 | G12: 0 | H12: 0 | I12: 1 | J12: Varies from week to week | K12: Varies from weekend to weekend | L12: 0 | M12: 0 | N12: 0 | O12: 0 | P12: 1 | Q12: 1 | AA12: Secondary reason | AB12: Secondary reason | AC12: Not applicable to my device(s) | AD12: Not a reason | AE12: Main reason | AF12: Not applicable to my device(s) | AG12: Secondary reason | AH12: Secondary reason | AI12: All weekdays | AJ12: Both Saturday and Sunday | AK12: Irregular times (no set times) | AL12: Some college but no degree | AM12: Yes | AN12: Yes | AO12: Yes | AP12: Yes | AQ12: Yes | AR12: Disabled, not able to work | AS12: Female | AT12: Some college but no degree | AU12: 1 | AV12: 0 | AW12: 0 | AX12: 0 | AY12: 0 | AZ12: 42_57
A13: 0 | B13: 1 | C13: 0 | D13: 0 | E13: 0 | F13: 1 | G13: 0 | H13: 1 | I13: 0 | J13: All weekdays | K13: Both Saturday and Sunday | L13: 0 | M13: 1 | N13: 0 | O13: 1 | P13: 0 | Q13: 0 | AA13: Not a reason | AB13: Main reason | AC13: Secondary reason | AD13: Secondary reason | AE13: Not a reason | AF13: Not a reason | AG13: Secondary reason | AH13: Not a reason | AI13: All weekdays | AJ13: Both Saturday and Sunday | AK13: Always (day and night) | AL13: Graduate degree | AM13: Yes | AN13: Yes | AO13: Yes | AP13: Yes | AQ13: No | AR13: Employed full-time | AS13: Female | AT13: Graduate degree | AU13: 0 | AV13: 0 | AW13: 0 | AX13: 1 | AY13: 0 | AZ13: 42_57
A14: 1 | B14: 0 | C14: 0 | D14: 0 | E14: 0 | F14: 1 | G14: 0 | H14: 0 | I14: 0 | J14: All weekdays | K14: Both Saturday and Sunday | L14: 0 | M14: 1 | N14: 0 | O14: 0 | P14: 0 | Q14: 0 | AA14: Not applicable to my device(s) | AB14: Main reason | AC14: Secondary reason | AD14: Secondary reason | AE14: Not applicable to my device(s) | AF14: Not applicable to my device(s) | AG14: Not a reason | AH14: Not a reason | AI14: All weekdays | AJ14: Both Saturday and Sunday | AK14: Daytime only | AL14: College graduate | AM14: Yes | AN14: Yes | AO14: Yes | AP14: Maybe | AQ14: Yes | AR14: Employed full-time | AS14: Female | AT14: College graduate | AU14: 0 | AV14: 0 | AW14: 0 | AX14: 1 | AY14: 0 | AZ14: 58_76
A15: 1 | B15: 0 | C15: 0 | D15: 0 | E15: 0 | F15: 1 | G15: 1 | H15: 0 | I15: 0 | J15: All weekdays | K15: Varies from weekend to weekend | L15: 0 | M15: 0 | N15: 1 | O15: 0 | P15: 0 | Q15: 0 | AA15: Secondary reason | AB15: Secondary reason | AC15: Not a reason | AD15: Secondary reason | AE15: Main reason | AF15: Secondary reason | AG15: Secondary reason | AH15: Not a reason | AI15: All weekdays | AJ15: Varies from weekend to weekend | AK15: Daytime only | AL15: Graduate degree | AM15: Yes | AN15: Yes | AO15: Yes | AP15: Maybe | AQ15: Yes | AR15: Employed full-time | AS15: Female | AT15: Graduate degree | AU15: 0 | AV15: 0 | AW15: 0 | AX15: 0 | AY15: 1 | AZ15: 42_57
A16: 1 | B16: 0 | C16: 0 | D16: 0 | E16: 0 | F16: 1 | G16: 1 | H16: 0 | I16: 0 | J16: All weekdays | K16: Both Saturday and Sunday | L16: 0 | M16: 0 | N16: 1 | O16: 0 | P16: 0 | Q16: 0 | AA16: Secondary reason | AB16: Main reason | AC16: Not a reason | AD16: Main reason | AE16: Main reason | AF16: Secondary reason | AG16: Main reason | AH16: Secondary reason | AI16: All weekdays | AJ16: Both Saturday and Sunday | AK16: Always (day and night) | AL16: Some college but no degree | AM16: Yes | AN16: Yes | AO16: Yes | AP16: Maybe | AQ16: Yes | AR16: Retired, not looking for work | AS16: Female | AT16: Some college but no degree | AU16: 0 | AV16: 0 | AW16: 0 | AX16: 1 | AY16: 0 | AZ16: 42_57
A17: 1 | B17: 0 | C17: 0 | D17: 0 | E17: 0 | F17: 1 | G17: 0 | H17: 1 | I17: 0 | J17: All weekdays | K17: Both Saturday and Sunday | L17: 0 | M17: 1 | N17: 0 | O17: 0 | P17: 0 | Q17: 0 | AA17: Not applicable to my device(s) | AB17: Main reason | AC17: Main reason | AD17: Not a reason | AE17: Secondary reason | AF17: Not applicable to my device(s) | AG17: Not applicable to my device(s) | AH17: Not a reason | AI17: All weekdays | AJ17: Both Saturday and Sunday | AK17: Always (day and night) | AL17: College graduate | AM17: Maybe | AN17: Maybe | AO17: Maybe | AP17: Yes | AQ17: Maybe | AR17: Employed full-time | AS17: Female | AT17: College graduate | AU17: 0 | AV17: 0 | AW17: 0 | AX17: 1 | AY17: 0 | AZ17: 42_57
A18: 0 | B18: 1 | C18: 0 | D18: 0 | E18: 1 | F18: 0 | G18: 0 | H18: 0 | I18: 0 | L18: 1 | M18: 0 | N18: 0 | O18: 0 | P18: 0 | Q18: 0 | R18: 0 | S18: 0 | T18: 1 | U18: 0 | V18: 0 | W18: 0 | X18: 0 | Y18: 0 | Z18: 0 | AL18: High school graduate | AM18: Yes | AN18: No | AO18: No | AP18: No | AQ18: No | AR18: Retired, not looking for work | AS18: Female | AT18: High school graduate | AU18: 0 | AV18: 0 | AW18: 0 | AX18: 1 | AY18: 0 | AZ18: 58_76
A19: 0 | B19: 1 | C19: 0 | D19: 0 | E19: 1 | F19: 0 | G19: 0 | H19: 0 | I19: 0 | L19: 1 | M19: 0 | N19: 0 | O19: 0 | P19: 0 | Q19: 0 | R19: 0 | S19: 0 | T19: 1 | U19: 0 | V19: 0 | W19: 0 | X19: 1 | Y19: 0 | Z19: 0 | AL19: College graduate | AM19: Yes | AN19: Maybe | AO19: No | AP19: Maybe | AQ19: Maybe | AR19: Retired, not looking for work | AS19: Female | AT19: College graduate | AU19: 0 | AV19: 0 | AW19: 0 | AX19: 1 | AY19: 0 | AZ19: 58_76
A20: 0 | B20: 1 | C20: 0 | D20: 0 | E20: 1 | F20: 0 | G20: 0 | H20: 0 | I20: 0 | L20: 0 | M20: 0 | N20: 0 | O20: 0 | P20: 0 | Q20: 1 | AA20: Not a reason | AB20: Secondary reason | AC20: Main reason | AD20: Secondary reason | AE20: Not a reason | AF20: Not a reason | AG20: Not a reason | AH20: Not a reason | AI20: All weekdays | AJ20: Both Saturday and Sunday | AK20: Always (day and night) | AL20: Some college but no degree | AM20: Maybe | AN20: Maybe | AO20: Maybe | AP20: Maybe | AQ20: No | AR20: Employed full-time | AS20: Female | AT20: Some college but no degree | AU20: 1 | AV20: 0 | AW20: 0 | AX20: 0 | AY20: 0 | AZ20: 42_57
A21: 1 | B21: 0 | C21: 0 | D21: 0 | E21: 0 | F21: 0 | G21: 0 | H21: 0 | I21: 1 | J21: All weekdays | K21: Both Saturday and Sunday | L21: 1 | M21: 0 | N21: 0 | O21: 0 | P21: 0 | Q21: 0 | R21: 0 | S21: 1 | T21: 0 | U21: 0 | V21: 0 | W21: 0 | X21: 0 | Y21: 0 | Z21: 0 | AL21: Graduate degree | AM21: Maybe | AN21: Maybe | AO21: Maybe | AP21: Maybe | AQ21: No | AR21: Retired, not looking for work | AS21: Female | AT21: Graduate degree | AU21: 0 | AV21: 0 | AW21: 0 | AX21: 1 | AY21: 0 | AZ21: 58_76
A22: 0 | B22: 1 | C22: 0 | D22: 0 | E22: 1 | F22: 0 | G22: 0 | H22: 0 | I22: 0 | L22: 0 | M22: 1 | N22: 0 | O22: 0 | P22: 0 | Q22: 0 | AA22: Main reason | AB22: Main reason | AC22: Main reason | AD22: Main reason | AE22: Main reason | AF22: Main reason | AG22: Main reason | AH22: Main reason | AI22: All weekdays | AJ22: Both Saturday and Sunday | AK22: Always (day and night) | AL22: High school graduate | AM22: Maybe | AN22: Yes | AO22: Yes | AP22: Yes | AQ22: Yes | AR22: Employed part-time | AS22: Female | AT22: High school graduate | AU22: 1 | AV22: 0 | AW22: 0 | AX22: 0 | AY22: 0 | AZ22: 42_57
A23: 1 | B23: 0 | C23: 0 | D23: 0 | E23: 0 | F23: 0 | G23: 0 | H23: 0 | I23: 1 | J23: Varies from week to week | K23: Varies from weekend to weekend | L23: 1 | M23: 0 | N23: 0 | O23: 0 | P23: 0 | Q23: 0 | R23: 0 | S23: 0 | T23: 0 | U23: 0 | V23: 0 | W23: 0 | X23: 1 | Y23: 0 | Z23: 0 | AL23: College graduate | AM23: No | AR23: Employed part-time | AS23: Female | AT23: College graduate | AU23: 0 | AV23: 0 | AW23: 0 | AX23: 1 | AY23: 0 | AZ23: 58_76
A24: 1 | B24: 0 | C24: 0 | D24: 0 | E24: 1 | F24: 0 | G24: 0 | H24: 0 | I24: 0 | L24: 1 | M24: 0 | N24: 0 | O24: 0 | P24: 0 | Q24: 0 | R24: 1 | S24: 0 | T24: 0 | U24: 0 | V24: 0 | W24: 0 | X24: 0 | Y24: 0 | Z24: 0 | AL24: College graduate | AM24: Yes | AN24: Yes | AO24: Yes | AP24: Yes | AQ24: Yes | AR24: Employed full-time | AS24: Female | AT24: College graduate | AU24: 1 | AV24: 0 | AW24: 0 | AX24: 0 | AY24: 0 | AZ24: 42_57
A25: 0 | B25: 1 | C25: 0 | D25: 0 | E25: 1 | F25: 0 | G25: 0 | H25: 0 | I25: 0 | L25: 1 | M25: 0 | N25: 0 | O25: 0 | P25: 0 | Q25: 0 | R25: 0 | S25: 1 | T25: 0 | U25: 0 | V25: 0 | W25: 0 | X25: 0 | Y25: 0 | Z25: 0 | AL25: High school graduate | AM25: No | AR25: Employed full-time | AS25: Female | AT25: High school graduate | AU25: 1 | AV25: 0 | AW25: 0 | AX25: 0 | AY25: 0 | AZ25: 58_76
A26: 0 | B26: 1 | C26: 0 | D26: 0 | E26: 1 | F26: 0 | G26: 0 | H26: 0 | I26: 0 | L26: 1 | M26: 0 | N26: 0 | O26: 0 | P26: 0 | Q26: 0 | R26: 0 | S26: 0 | T26: 1 | U26: 0 | V26: 0 | W26: 0 | X26: 0 | Y26: 0 | Z26: 0 | AL26: College graduate | AM26: Yes | AN26: No | AO26: Yes | AP26: Yes | AQ26: Maybe | AR26: Disabled, not able to work | AS26: Female | AT26: College graduate | AU26: 0 | AV26: 0 | AW26: 0 | AX26: 1 | AY26: 0 | AZ26: 58_76
A27: 1 | B27: 0 | C27: 0 | D27: 0 | E27: 0 | F27: 1 | G27: 0 | H27: 0 | I27: 0 | J27: All weekdays | K27: Both Saturday and Sunday | L27: 0 | M27: 1 | N27: 0 | O27: 0 | P27: 0 | Q27: 0 | AA27: Secondary reason | AB27: Main reason | AC27: Main reason | AD27: Secondary reason | AE27: Secondary reason | AF27: Secondary reason | AG27: Secondary reason | AH27: Not a reason | AI27: All weekdays | AJ27: Both Saturday and Sunday | AK27: Always (day and night) | AL27: Graduate degree | AM27: Yes | AN27: Yes | AO27: Yes | AP27: Yes | AQ27: Yes | AR27: Retired, not looking for work | AS27: Female | AT27: Graduate degree | AU27: 0 | AV27: 0 | AW27: 0 | AX27: 1 | AY27: 0 | AZ27: 58_76
A28: 0 | B28: 1 | C28: 0 | D28: 0 | E28: 1 | F28: 0 | G28: 0 | H28: 0 | I28: 0 | L28: 0 | M28: 1 | N28: 0 | O28: 0 | P28: 1 | Q28: 0 | AA28: Not a reason | AB28: Main reason | AC28: Not a reason | AD28: Main reason | AE28: Not a reason | AF28: Not a reason | AG28: Not a reason | AH28: Not a reason | AI28: None | AJ28: None | AL28: Graduate degree | AM28: No | AR28: Not employed, but looking for work | AS28: Female | AT28: Graduate degree | AU28: 0 | AV28: 0 | AW28: 0 | AX28: 0 | AY28: 1 | AZ28: 42_57
A29: 1 | B29: 0 | C29: 0 | D29: 0 | E29: 1 | F29: 0 | G29: 0 | H29: 0 | I29: 0 | L29: 1 | M29: 0 | N29: 0 | O29: 0 | P29: 0 | Q29: 0 | R29: 0 | S29: 0 | T29: 0 | U29: 0 | V29: 0 | W29: 1 | X29: 0 | Y29: 0 | Z29: 0 | AL29: Graduate degree | AM29: Maybe | AN29: Maybe | AO29: Yes | AP29: Yes | AQ29: Yes | AR29: Employed full-time | AS29: Female | AT29: Graduate degree | AU29: 0 | AV29: 0 | AW29: 0 | AX29: 1 | AY29: 0 | AZ29: 42_57
A30: 1 | B30: 0 | C30: 0 | D30: 0 | E30: 0 | F30: 1 | G30: 1 | H30: 0 | I30: 0 | J30: All weekdays | K30: Varies from weekend to weekend | L30: 0 | M30: 0 | N30: 1 | O30: 0 | P30: 0 | Q30: 0 | AA30: Not a reason | AB30: Main reason | AC30: Not a reason | AD30: Main reason | AE30: Secondary reason | AF30: Not a reason | AG30: Not a reason | AH30: Secondary reason | AI30: All weekdays | AJ30: Varies from weekend to weekend | AK30: Daytime only | AL30: Some college but no degree | AM30: Yes | AN30: Yes | AO30: Yes | AP30: Yes | AQ30: Yes | AR30: Employed full-time | AS30: Female | AT30: Some college but no degree | AU30: 0 | AV30: 0 | AW30: 0 | AX30: 1 | AY30: 0 | AZ30: 42_57
A31: 0 | B31: 1 | C31: 0 | D31: 0 | E31: 1 | F31: 0 | G31: 0 | H31: 0 | I31: 0 | L31: 1 | M31: 0 | N31: 0 | O31: 0 | P31: 0 | Q31: 0 | R31: 0 | S31: 0 | T31: 0 | U31: 0 | V31: 0 | W31: 0 | X31: 0 | Y31: 0 | Z31: 1 | AL31: Graduate degree | AM31: Maybe | AN31: Yes | AO31: No | AP31: Yes | AQ31: No | AR31: Retired, not looking for work | AS31: Female | AT31: Graduate degree | AU31: 0 | AV31: 0 | AW31: 0 | AX31: 1 | AY31: 0 | AZ31: 58_76
A32: 0 | B32: 1 | C32: 0 | D32: 0 | E32: 0 | F32: 0 | G32: 0 | H32: 0 | I32: 1 | J32: All weekdays | K32: Both Saturday and Sunday | L32: 1 | M32: 0 | N32: 0 | O32: 0 | P32: 0 | Q32: 0 | R32: 0 | S32: 0 | T32: 0 | U32: 0 | V32: 0 | W32: 1 | X32: 0 | Y32: 0 | Z32: 1 | AL32: Some college but no degree | AM32: Yes | AN32: Maybe | AO32: No | AP32: Maybe | AQ32: Yes | AR32: Employed full-time | AS32: Female | AT32: Some college but no degree | AU32: 0 | AV32: 0 | AW32: 0 | AX32: 1 | AY32: 0 | AZ32: 58_76
A33: 1 | B33: 0 | C33: 0 | D33: 0 | E33: 0 | F33: 1 | G33: 0 | H33: 0 | I33: 0 | J33: All weekdays | K33: Both Saturday and Sunday | L33: 0 | M33: 1 | N33: 0 | O33: 0 | P33: 0 | Q33: 0 | AA33: Not applicable to my device(s) | AB33: Main reason | AC33: Secondary reason | AD33: Not a reason | AE33: Not a reason | AF33: Not applicable to my device(s) | AG33: Not a reason | AH33: Not a reason | AI33: All weekdays | AJ33: Both Saturday and Sunday | AK33: Daytime only | AL33: Graduate degree | AM33: Maybe | AN33: Maybe | AO33: Yes | AP33: Yes | AQ33: Yes | AR33: Retired, not looking for work | AS33: Female | AT33: Graduate degree | AU33: 0 | AV33: 0 | AW33: 0 | AX33: 1 | AY33: 0 | AZ33: 58_76
A34: 1 | B34: 0 | C34: 0 | D34: 0 | E34: 0 | F34: 0 | G34: 0 | H34: 0 | I34: 1 | J34: All weekdays | K34: Both Saturday and Sunday | L34: 0 | M34: 1 | N34: 0 | O34: 0 | P34: 0 | Q34: 0 | AA34: Not applicable to my device(s) | AB34: Main reason | AC34: Not a reason | AD34: Not applicable to my device(s) | AE34: Not applicable to my device(s) | AF34: Not applicable to my device(s) | AG34: Not applicable to my device(s) | AH34: Not a reason | AI34: Some weekdays | AJ34: Varies from weekend to weekend | AK34: Daytime only | AL34: Graduate degree | AM34: Yes | AN34: Maybe | AO34: Maybe | AP34: Maybe | AQ34: Maybe | AR34: Employed full-time | AS34: Female | AT34: Graduate degree | AU34: 0 | AV34: 0 | AW34: 0 | AX34: 1 | AY34: 0 | AZ34: 58_76
A35: 0 | B35: 1 | C35: 0 | D35: 0 | E35: 0 | F35: 0 | G35: 0 | H35: 1 | I35: 0 | J35: Some weekdays | K35: Varies from weekend to weekend | L35: 0 | M35: 1 | N35: 0 | O35: 0 | P35: 0 | Q35: 0 | AA35: Not a reason | AB35: Secondary reason | AC35: Secondary reason | AD35: Main reason | AE35: Main reason | AF35: Secondary reason | AG35: Not applicable to my device(s) | AH35: Not a reason | AI35: Varies from week to week | AJ35: Varies from weekend to weekend | AK35: Always (day and night) | AL35: College graduate | AM35: Yes | AN35: Maybe | AO35: Maybe | AP35: Maybe | AQ35: Maybe | AR35: Disabled, not able to work | AS35: Female | AT35: College graduate | AU35: 1 | AV35: 0 | AW35: 0 | AX35: 0 | AY35: 0 | AZ35: 42_57
A36: 1 | B36: 0 | C36: 0 | D36: 0 | E36: 1 | F36: 0 | G36: 0 | H36: 0 | I36: 0 | L36: 0 | M36: 0 | N36: 0 | O36: 0 | P36: 0 | Q36: 1 | AA36: Secondary reason | AB36: Not a reason | AC36: Not a reason | AD36: Not applicable to my device(s) | AE36: Main reason | AF36: Not a reason | AG36: Main reason | AH36: Not a reason | AI36: None | AJ36: None | AL36: College graduate | AM36: No | AR36: Disabled, not able to work | AS36: Female | AT36: College graduate | AU36: 1 | AV36: 0 | AW36: 0 | AX36: 0 | AY36: 0 | AZ36: 58_76
A37: 1 | B37: 0 | C37: 0 | D37: 0 | E37: 0 | F37: 1 | G37: 0 | H37: 0 | I37: 0 | J37: Varies from week to week | K37: Varies from weekend to weekend | L37: 0 | M37: 0 | N37: 1 | O37: 0 | P37: 0 | Q37: 0 | AA37: Secondary reason | AB37: Secondary reason | AC37: Not a reason | AD37: Not a reason | AE37: Main reason | AF37: Not a reason | AG37: Secondary reason | AH37: Main reason | AI37: All weekdays | AJ37: Both Saturday and Sunday | AK37: Always (day and night) | AL37: College graduate | AM37: Maybe | AN37: Maybe | AO37: Yes | AP37: Maybe | AQ37: Maybe | AR37: Disabled, not able to work | AS37: Female | AT37: College graduate | AU37: 0 | AV37: 0 | AW37: 0 | AX37: 1 | AY37: 0 | AZ37: 58_76
A38: 1 | B38: 0 | C38: 0 | D38: 0 | E38: 0 | F38: 0 | G38: 0 | H38: 0 | I38: 1 | J38: Varies from week to week | K38: Varies from weekend to weekend | L38: 0 | M38: 1 | N38: 1 | O38: 0 | P38: 0 | Q38: 0 | AA38: Secondary reason | AB38: Secondary reason | AC38: Not a reason | AD38: Not a reason | AE38: Main reason | AF38: Not a reason | AG38: Not a reason | AH38: Not a reason | AI38: Varies from week to week | AJ38: Varies from weekend to weekend | AK38: Daytime only | AL38: College graduate | AM38: Maybe | AN38: Yes | AO38: Yes | AP38: Maybe | AQ38: Yes | AR38: Employed full-time | AS38: Female | AT38: College graduate | AU38: 0 | AV38: 0 | AW38: 0 | AX38: 1 | AY38: 0 | AZ38: 58_76
A39: 1 | B39: 0 | C39: 0 | D39: 0 | E39: 0 | F39: 1 | G39: 1 | H39: 1 | I39: 0 | J39: All weekdays | K39: Varies from weekend to weekend | L39: 0 | M39: 0 | N39: 1 | O39: 0 | P39: 0 | Q39: 0 | AA39: Not applicable to my device(s) | AB39: Main reason | AC39: Secondary reason | AD39: Secondary reason | AE39: Main reason | AF39: Not applicable to my device(s) | AG39: Secondary reason | AH39: Not applicable to my device(s) | AI39: All weekdays | AJ39: Both Saturday and Sunday | AK39: Always (day and night) | AL39: Graduate degree | AM39: Yes | AN39: Yes | AO39: Yes | AP39: Yes | AQ39: Maybe | AR39: Retired, not looking for work | AS39: Female | AT39: Graduate degree | AU39: 0 | AV39: 0 | AW39: 0 | AX39: 1 | AY39: 0 | AZ39: 58_76
A40: 1 | B40: 0 | C40: 0 | D40: 0 | E40: 1 | F40: 0 | G40: 0 | H40: 0 | I40: 0 | L40: 1 | M40: 0 | N40: 0 | O40: 0 | P40: 0 | Q40: 0 | R40: 0 | S40: 0 | T40: 1 | U40: 1 | V40: 0 | W40: 0 | X40: 0 | Y40: 0 | Z40: 0 | AL40: College graduate | AM40: Yes | AN40: Yes | AO40: No | AP40: Yes | AQ40: Maybe | AR40: Disabled, not able to work | AS40: Female | AT40: College graduate | AU40: 0 | AV40: 0 | AW40: 0 | AX40: 1 | AY40: 0 | AZ40: 58_76
...

Sheet Clean
A1: Own a smart phone_Yes-iPhone (iApple/iOS) | B1: Own a smart phone_Yes-Android (Samsung Galaxy, Google Pixel, OnePlus, Motorola, Nokia) | C1: Own a smart phone_Yes, some other smartphone (please provide) | D1: Own a smart phone_No | E1: Smartphone for activity tracking_No | F1: Smartphone for activity tracking_Fitness and workout monitoring (heart rate, step tracking, jogging, etc.) | G1: Smartphone for activity tracking_Health tracking (blood oxygen, heart rhythm, women's health such as ovulation tracking, etc.) | H1: Smartphone for activity tracking_Sleep monitoring (sleep duration, sleep quality, etc.) | I1: Smartphone for activity tracking_Other activity tracking (please describe) | J1: Weekdays smartphone activity tracked | K1: Weekends smartphone activity tracked | L1: Wearable device ownership_None | M1: Wearable device ownership_Fitbit | N1: Wearable device ownership_Apple Watch | O1: Wearable device ownership_Garmin | P1: Wearable device ownership_Samsung | Q1: Wearable device ownership_Other | R1: Reasons for not owning wearable devices_I want one, I just don't have one yet | S1: Reasons for not owning wearable devices_No particular reason | T1: Reasons for not owning wearable devices_Too expensive | U1: Reasons for not owning wearable devices_Too hard to read | V1: Reasons for not owning wearable devices_Don't trust that they work correctly | W1: Reasons for not owning wearable devices_Don't know enough about them | X1: Reasons for not owning wearable devices_Not interested in tracking | Y1: Reasons for not owning wearable devices_Privacy reasons | Z1: Reasons for not owning wearable devices_Some other reason not listed (please provide) | AA1: Wearable device usage by reason_Apps (social media, news, etc.) | AB1: Wearable device usage by reason_Fitness and workout monitoring (heart rate, step tracking, jogging, etc.) | AC1: Wearable device usage by reason_Sleep monitoring (sleep duration, sleep quality, etc.) | AD1: Wearable device usage by reason_Health tracking (blood oxygen, heart rhythm, women's health such as ovulation tracking, etc.) | AE1: Wearable device usage by reason_Phone calls, emails, texting | AF1: Wearable device usage by reason_Music, audiobooks, or podcasts | AG1: Wearable device usage by reason_Navigation (GPS) | AH1: Wearable device usage by reason_Wear for fashion | AI1: Weekdays wearable device worn | AJ1: Weekends wearable device worn | AK1: Time of day wearable device worn | AL1: Highest level of education | AM1: Interest in future research opportunities | AN1: Types of activities comfortable sharing _Health tracking (blood oxygen, heart rhythm, women's health such as ovulation tracking, etc.) | AO1: Types of activities comfortable sharing _Fitness and workout monitoring (heart rate, step tracking, jogging, etc.) | AP1: Types of activities comfortable sharing _Sleep monitoring (sleep duration, sleep quality, etc.) | AQ1: Types of activities comfortable sharing _Self-reported measures from health and fitness apps (mindfulness and mood, water intake, food logs, women's health, etc.) | AR1: Employment Status | AS1: Gender | AT1: Race / Ethnicity_Black or African American | AU1: Race / Ethnicity_Asian or Asian American | AV1: Race / Ethnicity_Hispanic | AW1: Race / Ethnicity_White or Caucasian | AX1: Race / Ethnicity - Other | AY1: generation_age_group
A2: 0 | B2: 1 | C2: 0 | D2: 0 | E2: 1 | F2: 0 | G2: 0 | H2: 0 | I2: 0 | L2: 1 | M2: 0 | N2: 0 | O2: 0 | P2: 0 | Q2: 0 | R2: 0 | S2: 1 | T2: 0 | U2: 0 | V2: 0 | W2: 0 | X2: 0 | Y2: 0 | Z2: 0 | AL2: Graduate degree | AM2: No | AR2: Employed full-time | AS2: Female | AT2: 0 | AU2: 0 | AV2: 0 | AW2: 1 | AX2: 0 | AY2: 42_57
A3: 1 | B3: 0 | C3: 0 | D3: 0 | E3: 0 | F3: 1 | G3: 0 | H3: 0 | I3: 0 | J3: Varies from week to week | K3: Varies from weekend to weekend | L3: 0 | M3: 0 | N3: 1 | O3: 0 | P3: 0 | Q3: 0 | AA3: Secondary reason | AB3: Main reason | AC3: Not a reason | AD3: Secondary reason | AE3: Main reason | AF3: Not a reason | AG3: Not a reason | AH3: Not a reason | AI3: Varies from week to week | AJ3: Varies from weekend to weekend | AK3: Daytime only | AL3: Graduate degree | AM3: Maybe | AN3: Maybe | AO3: Yes | AP3: Maybe | AQ3: Maybe | AR3: Employed full-time | AS3: Female | AT3: 0 | AU3: 0 | AV3: 0 | AW3: 1 | AX3: 0 | AY3: 42_57
A4: 1 | B4: 0 | C4: 0 | D4: 0 | E4: 0 | F4: 1 | G4: 1 | H4: 1 | I4: 0 | J4: All weekdays | K4: Both Saturday and Sunday | L4: 0 | M4: 0 | N4: 1 | O4: 0 | P4: 0 | Q4: 0 | AA4: Not a reason | AB4: Main reason | AC4: Secondary reason | AD4: Secondary reason | AE4: Main reason | AF4: Not a reason | AG4: Not applicable to my device(s) | AH4: Secondary reason | AI4: All weekdays | AJ4: Both Saturday and Sunday | AK4: Daytime only | AL4: Graduate degree | AM4: Yes | AN4: Yes | AO4: Yes | AP4: Maybe | AQ4: Yes | AR4: Employed full-time | AS4: Male | AT4: 1 | AU4: 0 | AV4: 0 | AW4: 0 | AX4: 0 | AY4: 26_41
A5: 1 | B5: 0 | C5: 0 | D5: 0 | E5: 0 | F5: 0 | G5: 0 | H5: 0 | I5: 1 | J5: Varies from week to week | K5: Varies from weekend to weekend | L5: 1 | M5: 0 | N5: 0 | O5: 0 | P5: 0 | Q5: 0 | R5: 0 | S5: 1 | T5: 0 | U5: 0 | V5: 0 | W5: 0 | X5: 0 | Y5: 0 | Z5: 0 | AL5: Some college but no degree | AM5: Yes | AN5: Yes | AO5: Yes | AP5: Yes | AQ5: Maybe | AR5: Retired, not looking for work | AS5: Male | AT5: 1 | AU5: 0 | AV5: 0 | AW5: 0 | AX5: 0 | AY5: 58_76
A6: 1 | B6: 0 | C6: 0 | D6: 0 | E6: 0 | F6: 1 | G6: 0 | H6: 1 | I6: 0 | J6: All weekdays | K6: Both Saturday and Sunday | L6: 0 | M6: 0 | N6: 1 | O6: 0 | P6: 0 | Q6: 0 | AA6: Not a reason | AB6: Main reason | AC6: Secondary reason | AD6: Secondary reason | AE6: Secondary reason | AF6: Secondary reason | AG6: Secondary reason | AH6: Secondary reason | AI6: All weekdays | AJ6: Both Saturday and Sunday | AK6: Always (day and night) | AL6: Graduate degree | AM6: Maybe | AN6: No | AO6: Yes | AP6: Yes | AQ6: No | AR6: Disabled, not able to work | AS6: Female | AT6: 0 | AU6: 0 | AV6: 0 | AW6: 1 | AX6: 0 | AY6: 58_76
A7: 1 | B7: 0 | C7: 0 | D7: 0 | E7: 0 | F7: 1 | G7: 0 | H7: 0 | I7: 0 | J7: All weekdays | K7: Both Saturday and Sunday | L7: 0 | M7: 1 | N7: 0 | O7: 0 | P7: 0 | Q7: 0 | AA7: Not applicable to my device(s) | AB7: Main reason | AC7: Secondary reason | AD7: Main reason | AE7: Not a reason | AF7: Not applicable to my device(s) | AG7: Not applicable to my device(s) | AH7: Not a reason | AI7: All weekdays | AJ7: Both Saturday and Sunday | AK7: Always (day and night) | AL7: Graduate degree | AM7: Maybe | AN7: No | AO7: Yes | AP7: Yes | AQ7: Maybe | AR7: Retired, not looking for work | AS7: Female | AT7: 0 | AU7: 0 | AV7: 0 | AW7: 1 | AX7: 0 | AY7: 58_76
A8: 0 | B8: 1 | C8: 0 | D8: 0 | E8: 0 | F8: 0 | G8: 0 | H8: 0 | I8: 1 | J8: Varies from week to week | K8: Varies from weekend to weekend | L8: 1 | M8: 0 | N8: 0 | O8: 0 | P8: 0 | Q8: 0 | R8: 0 | S8: 0 | T8: 0 | U8: 0 | V8: 0 | W8: 0 | X8: 0 | Y8: 0 | Z8: 1 | AL8: Some college but no degree | AM8: No | AR8: Disabled, not able to work | AS8: Female | AT8: 0 | AU8: 0 | AV8: 0 | AW8: 1 | AX8: 0 | AY8: 58_76
A9: 1 | B9: 0 | C9: 0 | D9: 0 | E9: 0 | F9: 1 | G9: 0 | H9: 1 | I9: 0 | J9: All weekdays | K9: Both Saturday and Sunday | L9: 0 | M9: 1 | N9: 0 | O9: 0 | P9: 0 | Q9: 0 | AA9: Not a reason | AB9: Main reason | AC9: Secondary reason | AD9: Not a reason | AE9: Not a reason | AF9: Not a reason | AG9: Not applicable to my device(s) | AH9: Not a reason | AI9: All weekdays | AJ9: Both Saturday and Sunday | AK9: Always (day and night) | AL9: College graduate | AM9: Maybe | AN9: Maybe | AO9: Yes | AP9: Yes | AQ9: No | AR9: Employed part-time | AS9: Female | AT9: 0 | AU9: 0 | AV9: 0 | AW9: 1 | AX9: 0 | AY9: 58_76
A10: 1 | B10: 0 | C10: 0 | D10: 0 | E10: 1 | F10: 0 | G10: 0 | H10: 0 | I10: 0 | L10: 1 | M10: 0 | N10: 0 | O10: 0 | P10: 0 | Q10: 0 | R10: 1 | S10: 0 | T10: 0 | U10: 0 | V10: 0 | W10: 0 | X10: 0 | Y10: 0 | Z10: 0 | AL10: College graduate | AM10: Yes | AN10: Yes | AO10: Yes | AP10: Yes | AQ10: Maybe | AR10: Employed part-time | AS10: Female | AT10: 0 | AU10: 0 | AV10: 0 | AW10: 1 | AX10: 0 | AY10: 42_57
A11: 1 | B11: 0 | C11: 0 | D11: 0 | E11: 1 | F11: 0 | G11: 0 | H11: 0 | I11: 0 | L11: 1 | M11: 0 | N11: 0 | O11: 0 | P11: 0 | Q11: 0 | R11: 0 | S11: 0 | T11: 1 | U11: 0 | V11: 0 | W11: 0 | X11: 0 | Y11: 0 | Z11: 0 | AL11: Graduate degree | AM11: Yes | AN11: Yes | AO11: Maybe | AP11: Yes | AQ11: Yes | AR11: Not employed, but looking for work | AS11: Female | AT11: 0 | AU11: 1 | AV11: 0 | AW11: 0 | AX11: 0 | AY11: 42_57
A12: 0 | B12: 1 | C12: 0 | D12: 0 | E12: 0 | F12: 0 | G12: 0 | H12: 0 | I12: 1 | J12: Varies from week to week | K12: Varies from weekend to weekend | L12: 0 | M12: 0 | N12: 0 | O12: 0 | P12: 1 | Q12: 1 | AA12: Secondary reason | AB12: Secondary reason | AC12: Not applicable to my device(s) | AD12: Not a reason | AE12: Main reason | AF12: Not applicable to my device(s) | AG12: Secondary reason | AH12: Secondary reason | AI12: All weekdays | AJ12: Both Saturday and Sunday | AK12: Irregular times (no set times) | AL12: Some college but no degree | AM12: Yes | AN12: Yes | AO12: Yes | AP12: Yes | AQ12: Yes | AR12: Disabled, not able to work | AS12: Female | AT12: 1 | AU12: 0 | AV12: 0 | AW12: 0 | AX12: 0 | AY12: 42_57
A13: 0 | B13: 1 | C13: 0 | D13: 0 | E13: 0 | F13: 1 | G13: 0 | H13: 1 | I13: 0 | J13: All weekdays | K13: Both Saturday and Sunday | L13: 0 | M13: 1 | N13: 0 | O13: 1 | P13: 0 | Q13: 0 | AA13: Not a reason | AB13: Main reason | AC13: Secondary reason | AD13: Secondary reason | AE13: Not a reason | AF13: Not a reason | AG13: Secondary reason | AH13: Not a reason | AI13: All weekdays | AJ13: Both Saturday and Sunday | AK13: Always (day and night) | AL13: Graduate degree | AM13: Yes | AN13: Yes | AO13: Yes | AP13: Yes | AQ13: No | AR13: Employed full-time | AS13: Female | AT13: 0 | AU13: 0 | AV13: 0 | AW13: 1 | AX13: 0 | AY13: 42_57
A14: 1 | B14: 0 | C14: 0 | D14: 0 | E14: 0 | F14: 1 | G14: 0 | H14: 0 | I14: 0 | J14: All weekdays | K14: Both Saturday and Sunday | L14: 0 | M14: 1 | N14: 0 | O14: 0 | P14: 0 | Q14: 0 | AA14: Not applicable to my device(s) | AB14: Main reason | AC14: Secondary reason | AD14: Secondary reason | AE14: Not applicable to my device(s) | AF14: Not applicable to my device(s) | AG14: Not a reason | AH14: Not a reason | AI14: All weekdays | AJ14: Both Saturday and Sunday | AK14: Daytime only | AL14: College graduate | AM14: Yes | AN14: Yes | AO14: Yes | AP14: Maybe | AQ14: Yes | AR14: Employed full-time | AS14: Female | AT14: 0 | AU14: 0 | AV14: 0 | AW14: 1 | AX14: 0 | AY14: 58_76
A15: 1 | B15: 0 | C15: 0 | D15: 0 | E15: 0 | F15: 1 | G15: 1 | H15: 0 | I15: 0 | J15: All weekdays | K15: Varies from weekend to weekend | L15: 0 | M15: 0 | N15: 1 | O15: 0 | P15: 0 | Q15: 0 | AA15: Secondary reason | AB15: Secondary reason | AC15: Not a reason | AD15: Secondary reason | AE15: Main reason | AF15: Secondary reason | AG15: Secondary reason | AH15: Not a reason | AI15: All weekdays | AJ15: Varies from weekend to weekend | AK15: Daytime only | AL15: Graduate degree | AM15: Yes | AN15: Yes | AO15: Yes | AP15: Maybe | AQ15: Yes | AR15: Employed full-time | AS15: Female | AT15: 0 | AU15: 0 | AV15: 0 | AW15: 0 | AX15: 1 | AY15: 42_57
A16: 1 | B16: 0 | C16: 0 | D16: 0 | E16: 0 | F16: 1 | G16: 1 | H16: 0 | I16: 0 | J16: All weekdays | K16: Both Saturday and Sunday | L16: 0 | M16: 0 | N16: 1 | O16: 0 | P16: 0 | Q16: 0 | AA16: Secondary reason | AB16: Main reason | AC16: Not a reason | AD16: Main reason | AE16: Main reason | AF16: Secondary reason | AG16: Main reason | AH16: Secondary reason | AI16: All weekdays | AJ16: Both Saturday and Sunday | AK16: Always (day and night) | AL16: Some college but no degree | AM16: Yes | AN16: Yes | AO16: Yes | AP16: Maybe | AQ16: Yes | AR16: Retired, not looking for work | AS16: Female | AT16: 0 | AU16: 0 | AV16: 0 | AW16: 1 | AX16: 0 | AY16: 42_57
A17: 1 | B17: 0 | C17: 0 | D17: 0 | E17: 0 | F17: 1 | G17: 0 | H17: 1 | I17: 0 | J17: All weekdays | K17: Both Saturday and Sunday | L17: 0 | M17: 1 | N17: 0 | O17: 0 | P17: 0 | Q17: 0 | AA17: Not applicable to my device(s) | AB17: Main reason | AC17: Main reason | AD17: Not a reason | AE17: Secondary reason | AF17: Not applicable to my device(s) | AG17: Not applicable to my device(s) | AH17: Not a reason | AI17: All weekdays | AJ17: Both Saturday and Sunday | AK17: Always (day and night) | AL17: College graduate | AM17: Maybe | AN17: Maybe | AO17: Maybe | AP17: Yes | AQ17: Maybe | AR17: Employed full-time | AS17: Female | AT17: 0 | AU17: 0 | AV17: 0 | AW17: 1 | AX17: 0 | AY17: 42_57
A18: 0 | B18: 1 | C18: 0 | D18: 0 | E18: 1 | F18: 0 | G18: 0 | H18: 0 | I18: 0 | L18: 1 | M18: 0 | N18: 0 | O18: 0 | P18: 0 | Q18: 0 | R18: 0 | S18: 0 | T18: 1 | U18: 0 | V18: 0 | W18: 0 | X18: 0 | Y18: 0 | Z18: 0 | AL18: High school graduate | AM18: Yes | AN18: No | AO18: No | AP18: No | AQ18: No | AR18: Retired, not looking for work | AS18: Female | AT18: 0 | AU18: 0 | AV18: 0 | AW18: 1 | AX18: 0 | AY18: 58_76
A19: 0 | B19: 1 | C19: 0 | D19: 0 | E19: 1 | F19: 0 | G19: 0 | H19: 0 | I19: 0 | L19: 1 | M19: 0 | N19: 0 | O19: 0 | P19: 0 | Q19: 0 | R19: 0 | S19: 0 | T19: 1 | U19: 0 | V19: 0 | W19: 0 | X19: 1 | Y19: 0 | Z19: 0 | AL19: College graduate | AM19: Yes | AN19: Maybe | AO19: No | AP19: Maybe | AQ19: Maybe | AR19: Retired, not looking for work | AS19: Female | AT19: 0 | AU19: 0 | AV19: 0 | AW19: 1 | AX19: 0 | AY19: 58_76
A20: 0 | B20: 1 | C20: 0 | D20: 0 | E20: 1 | F20: 0 | G20: 0 | H20: 0 | I20: 0 | L20: 0 | M20: 0 | N20: 0 | O20: 0 | P20: 0 | Q20: 1 | AA20: Not a reason | AB20: Secondary reason | AC20: Main reason | AD20: Secondary reason | AE20: Not a reason | AF20: Not a reason | AG20: Not a reason | AH20: Not a reason | AI20: All weekdays | AJ20: Both Saturday and Sunday | AK20: Always (day and night) | AL20: Some college but no degree | AM20: Maybe | AN20: Maybe | AO20: Maybe | AP20: Maybe | AQ20: No | AR20: Employed full-time | AS20: Female | AT20: 1 | AU20: 0 | AV20: 0 | AW20: 0 | AX20: 0 | AY20: 42_57
A21: 1 | B21: 0 | C21: 0 | D21: 0 | E21: 0 | F21: 0 | G21: 0 | H21: 0 | I21: 1 | J21: All weekdays | K21: Both Saturday and Sunday | L21: 1 | M21: 0 | N21: 0 | O21: 0 | P21: 0 | Q21: 0 | R21: 0 | S21: 1 | T21: 0 | U21: 0 | V21: 0 | W21: 0 | X21: 0 | Y21: 0 | Z21: 0 | AL21: Graduate degree | AM21: Maybe | AN21: Maybe | AO21: Maybe | AP21: Maybe | AQ21: No | AR21: Retired, not looking for work | AS21: Female | AT21: 0 | AU21: 0 | AV21: 0 | AW21: 1 | AX21: 0 | AY21: 58_76
A22: 0 | B22: 1 | C22: 0 | D22: 0 | E22: 1 | F22: 0 | G22: 0 | H22: 0 | I22: 0 | L22: 0 | M22: 1 | N22: 0 | O22: 0 | P22: 0 | Q22: 0 | AA22: Main reason | AB22: Main reason | AC22: Main reason | AD22: Main reason | AE22: Main reason | AF22: Main reason | AG22: Main reason | AH22: Main reason | AI22: All weekdays | AJ22: Both Saturday and Sunday | AK22: Always (day and night) | AL22: High school graduate | AM22: Maybe | AN22: Yes | AO22: Yes | AP22: Yes | AQ22: Yes | AR22: Employed part-time | AS22: Female | AT22: 1 | AU22: 0 | AV22: 0 | AW22: 0 | AX22: 0 | AY22: 42_57
A23: 1 | B23: 0 | C23: 0 | D23: 0 | E23: 0 | F23: 0 | G23: 0 | H23: 0 | I23: 1 | J23: Varies from week to week | K23: Varies from weekend to weekend | L23: 1 | M23: 0 | N23: 0 | O23: 0 | P23: 0 | Q23: 0 | R23: 0 | S23: 0 | T23: 0 | U23: 0 | V23: 0 | W23: 0 | X23: 1 | Y23: 0 | Z23: 0 | AL23: College graduate | AM23: No | AR23: Employed part-time | AS23: Female | AT23: 0 | AU23: 0 | AV23: 0 | AW23: 1 | AX23: 0 | AY23: 58_76
A24: 1 | B24: 0 | C24: 0 | D24: 0 | E24: 1 | F24: 0 | G24: 0 | H24: 0 | I24: 0 | L24: 1 | M24: 0 | N24: 0 | O24: 0 | P24: 0 | Q24: 0 | R24: 1 | S24: 0 | T24: 0 | U24: 0 | V24: 0 | W24: 0 | X24: 0 | Y24: 0 | Z24: 0 | AL24: College graduate | AM24: Yes | AN24: Yes | AO24: Yes | AP24: Yes | AQ24: Yes | AR24: Employed full-time | AS24: Female | AT24: 1 | AU24: 0 | AV24: 0 | AW24: 0 | AX24: 0 | AY24: 42_57
A25: 0 | B25: 1 | C25: 0 | D25: 0 | E25: 1 | F25: 0 | G25: 0 | H25: 0 | I25: 0 | L25: 1 | M25: 0 | N25: 0 | O25: 0 | P25: 0 | Q25: 0 | R25: 0 | S25: 1 | T25: 0 | U25: 0 | V25: 0 | W25: 0 | X25: 0 | Y25: 0 | Z25: 0 | AL25: High school graduate | AM25: No | AR25: Employed full-time | AS25: Female | AT25: 1 | AU25: 0 | AV25: 0 | AW25: 0 | AX25: 0 | AY25: 58_76
A26: 0 | B26: 1 | C26: 0 | D26: 0 | E26: 1 | F26: 0 | G26: 0 | H26: 0 | I26: 0 | L26: 1 | M26: 0 | N26: 0 | O26: 0 | P26: 0 | Q26: 0 | R26: 0 | S26: 0 | T26: 1 | U26: 0 | V26: 0 | W26: 0 | X26: 0 | Y26: 0 | Z26: 0 | AL26: College graduate | AM26: Yes | AN26: No | AO26: Yes | AP26: Yes | AQ26: Maybe | AR26: Disabled, not able to work | AS26: Female | AT26: 0 | AU26: 0 | AV26: 0 | AW26: 1 | AX26: 0 | AY26: 58_76
A27: 1 | B27: 0 | C27: 0 | D27: 0 | E27: 0 | F27: 1 | G27: 0 | H27: 0 | I27: 0 | J27: All weekdays | K27: Both Saturday and Sunday | L27: 0 | M27: 1 | N27: 0 | O27: 0 | P27: 0 | Q27: 0 | AA27: Secondary reason | AB27: Main reason | AC27: Main reason | AD27: Secondary reason | AE27: Secondary reason | AF27: Secondary reason | AG27: Secondary reason | AH27: Not a reason | AI27: All weekdays | AJ27: Both Saturday and Sunday | AK27: Always (day and night) | AL27: Graduate degree | AM27: Yes | AN27: Yes | AO27: Yes | AP27: Yes | AQ27: Yes | AR27: Retired, not looking for work | AS27: Female | AT27: 0 | AU27: 0 | AV27: 0 | AW27: 1 | AX27: 0 | AY27: 58_76
A28: 0 | B28: 1 | C28: 0 | D28: 0 | E28: 1 | F28: 0 | G28: 0 | H28: 0 | I28: 0 | L28: 0 | M28: 1 | N28: 0 | O28: 0 | P28: 1 | Q28: 0 | AA28: Not a reason | AB28: Main reason | AC28: Not a reason | AD28: Main reason | AE28: Not a reason | AF28: Not a reason | AG28: Not a reason | AH28: Not a reason | AI28: None | AJ28: None | AL28: Graduate degree | AM28: No | AR28: Not employed, but looking for work | AS28: Female | AT28: 0 | AU28: 0 | AV28: 0 | AW28: 0 | AX28: 1 | AY28: 42_57
A29: 1 | B29: 0 | C29: 0 | D29: 0 | E29: 1 | F29: 0 | G29: 0 | H29: 0 | I29: 0 | L29: 1 | M29: 0 | N29: 0 | O29: 0 | P29: 0 | Q29: 0 | R29: 0 | S29: 0 | T29: 0 | U29: 0 | V29: 0 | W29: 1 | X29: 0 | Y29: 0 | Z29: 0 | AL29: Graduate degree | AM29: Maybe | AN29: Maybe | AO29: Yes | AP29: Yes | AQ29: Yes | AR29: Employed full-time | AS29: Female | AT29: 0 | AU29: 0 | AV29: 0 | AW29: 1 | AX29: 0 | AY29: 42_57
A30: 1 | B30: 0 | C30: 0 | D30: 0 | E30: 0 | F30: 1 | G30: 1 | H30: 0 | I30: 0 | J30: All weekdays | K30: Varies from weekend to weekend | L30: 0 | M30: 0 | N30: 1 | O30: 0 | P30: 0 | Q30: 0 | AA30: Not a reason | AB30: Main reason | AC30: Not a reason | AD30: Main reason | AE30: Secondary reason | AF30: Not a reason | AG30: Not a reason | AH30: Secondary reason | AI30: All weekdays | AJ30: Varies from weekend to weekend | AK30: Daytime only | AL30: Some college but no degree | AM30: Yes | AN30: Yes | AO30: Yes | AP30: Yes | AQ30: Yes | AR30: Employed full-time | AS30: Female | AT30: 0 | AU30: 0 | AV30: 0 | AW30: 1 | AX30: 0 | AY30: 42_57
A31: 0 | B31: 1 | C31: 0 | D31: 0 | E31: 1 | F31: 0 | G31: 0 | H31: 0 | I31: 0 | L31: 1 | M31: 0 | N31: 0 | O31: 0 | P31: 0 | Q31: 0 | R31: 0 | S31: 0 | T31: 0 | U31: 0 | V31: 0 | W31: 0 | X31: 0 | Y31: 0 | Z31: 1 | AL31: Graduate degree | AM31: Maybe | AN31: Yes | AO31: No | AP31: Yes | AQ31: No | AR31: Retired, not looking for work | AS31: Female | AT31: 0 | AU31: 0 | AV31: 0 | AW31: 1 | AX31: 0 | AY31: 58_76
A32: 0 | B32: 1 | C32: 0 | D32: 0 | E32: 0 | F32: 0 | G32: 0 | H32: 0 | I32: 1 | J32: All weekdays | K32: Both Saturday and Sunday | L32: 1 | M32: 0 | N32: 0 | O32: 0 | P32: 0 | Q32: 0 | R32: 0 | S32: 0 | T32: 0 | U32: 0 | V32: 0 | W32: 1 | X32: 0 | Y32: 0 | Z32: 1 | AL32: Some college but no degree | AM32: Yes | AN32: Maybe | AO32: No | AP32: Maybe | AQ32: Yes | AR32: Employed full-time | AS32: Female | AT32: 0 | AU32: 0 | AV32: 0 | AW32: 1 | AX32: 0 | AY32: 58_76
A33: 1 | B33: 0 | C33: 0 | D33: 0 | E33: 0 | F33: 1 | G33: 0 | H33: 0 | I33: 0 | J33: All weekdays | K33: Both Saturday and Sunday | L33: 0 | M33: 1 | N33: 0 | O33: 0 | P33: 0 | Q33: 0 | AA33: Not applicable to my device(s) | AB33: Main reason | AC33: Secondary reason | AD33: Not a reason | AE33: Not a reason | AF33: Not applicable to my device(s) | AG33: Not a reason | AH33: Not a reason | AI33: All weekdays | AJ33: Both Saturday and Sunday | AK33: Daytime only | AL33: Graduate degree | AM33: Maybe | AN33: Maybe | AO33: Yes | AP33: Yes | AQ33: Yes | AR33: Retired, not looking for work | AS33: Female | AT33: 0 | AU33: 0 | AV33: 0 | AW33: 1 | AX33: 0 | AY33: 58_76
A34: 1 | B34: 0 | C34: 0 | D34: 0 | E34: 0 | F34: 0 | G34: 0 | H34: 0 | I34: 1 | J34: All weekdays | K34: Both Saturday and Sunday | L34: 0 | M34: 1 | N34: 0 | O34: 0 | P34: 0 | Q34: 0 | AA34: Not applicable to my device(s) | AB34: Main reason | AC34: Not a reason | AD34: Not applicable to my device(s) | AE34: Not applicable to my device(s) | AF34: Not applicable to my device(s) | AG34: Not applicable to my device(s) | AH34: Not a reason | AI34: Some weekdays | AJ34: Varies from weekend to weekend | AK34: Daytime only | AL34: Graduate degree | AM34: Yes | AN34: Maybe | AO34: Maybe | AP34: Maybe | AQ34: Maybe | AR34: Employed full-time | AS34: Female | AT34: 0 | AU34: 0 | AV34: 0 | AW34: 1 | AX34: 0 | AY34: 58_76
A35: 0 | B35: 1 | C35: 0 | D35: 0 | E35: 0 | F35: 0 | G35: 0 | H35: 1 | I35: 0 | J35: Some weekdays | K35: Varies from weekend to weekend | L35: 0 | M35: 1 | N35: 0 | O35: 0 | P35: 0 | Q35: 0 | AA35: Not a reason | AB35: Secondary reason | AC35: Secondary reason | AD35: Main reason | AE35: Main reason | AF35: Secondary reason | AG35: Not applicable to my device(s) | AH35: Not a reason | AI35: Varies from week to week | AJ35: Varies from weekend to weekend | AK35: Always (day and night) | AL35: College graduate | AM35: Yes | AN35: Maybe | AO35: Maybe | AP35: Maybe | AQ35: Maybe | AR35: Disabled, not able to work | AS35: Female | AT35: 1 | AU35: 0 | AV35: 0 | AW35: 0 | AX35: 0 | AY35: 42_57
A36: 1 | B36: 0 | C36: 0 | D36: 0 | E36: 1 | F36: 0 | G36: 0 | H36: 0 | I36: 0 | L36: 0 | M36: 0 | N36: 0 | O36: 0 | P36: 0 | Q36: 1 | AA36: Secondary reason | AB36: Not a reason | AC36: Not a reason | AD36: Not applicable to my device(s) | AE36: Main reason | AF36: Not a reason | AG36: Main reason | AH36: Not a reason | AI36: None | AJ36: None | AL36: College graduate | AM36: No | AR36: Disabled, not able to work | AS36: Female | AT36: 1 | AU36: 0 | AV36: 0 | AW36: 0 | AX36: 0 | AY36: 58_76
A37: 1 | B37: 0 | C37: 0 | D37: 0 | E37: 0 | F37: 1 | G37: 0 | H37: 0 | I37: 0 | J37: Varies from week to week | K37: Varies from weekend to weekend | L37: 0 | M37: 0 | N37: 1 | O37: 0 | P37: 0 | Q37: 0 | AA37: Secondary reason | AB37: Secondary reason | AC37: Not a reason | AD37: Not a reason | AE37: Main reason | AF37: Not a reason | AG37: Secondary reason | AH37: Main reason | AI37: All weekdays | AJ37: Both Saturday and Sunday | AK37: Always (day and night) | AL37: College graduate | AM37: Maybe | AN37: Maybe | AO37: Yes | AP37: Maybe | AQ37: Maybe | AR37: Disabled, not able to work | AS37: Female | AT37: 0 | AU37: 0 | AV37: 0 | AW37: 1 | AX37: 0 | AY37: 58_76
A38: 1 | B38: 0 | C38: 0 | D38: 0 | E38: 0 | F38: 0 | G38: 0 | H38: 0 | I38: 1 | J38: Varies from week to week | K38: Varies from weekend to weekend | L38: 0 | M38: 1 | N38: 1 | O38: 0 | P38: 0 | Q38: 0 | AA38: Secondary reason | AB38: Secondary reason | AC38: Not a reason | AD38: Not a reason | AE38: Main reason | AF38: Not a reason | AG38: Not a reason | AH38: Not a reason | AI38: Varies from week to week | AJ38: Varies from weekend to weekend | AK38: Daytime only | AL38: College graduate | AM38: Maybe | AN38: Yes | AO38: Yes | AP38: Maybe | AQ38: Yes | AR38: Employed full-time | AS38: Female | AT38: 0 | AU38: 0 | AV38: 0 | AW38: 1 | AX38: 0 | AY38: 58_76
A39: 1 | B39: 0 | C39: 0 | D39: 0 | E39: 0 | F39: 1 | G39: 1 | H39: 1 | I39: 0 | J39: All weekdays | K39: Varies from weekend to weekend | L39: 0 | M39: 0 | N39: 1 | O39: 0 | P39: 0 | Q39: 0 | AA39: Not applicable to my device(s) | AB39: Main reason | AC39: Secondary reason | AD39: Secondary reason | AE39: Main reason | AF39: Not applicable to my device(s) | AG39: Secondary reason | AH39: Not applicable to my device(s) | AI39: All weekdays | AJ39: Both Saturday and Sunday | AK39: Always (day and night) | AL39: Graduate degree | AM39: Yes | AN39: Yes | AO39: Yes | AP39: Yes | AQ39: Maybe | AR39: Retired, not looking for work | AS39: Female | AT39: 0 | AU39: 0 | AV39: 0 | AW39: 1 | AX39: 0 | AY39: 58_76
A40: 1 | B40: 0 | C40: 0 | D40: 0 | E40: 1 | F40: 0 | G40: 0 | H40: 0 | I40: 0 | L40: 1 | M40: 0 | N40: 0 | O40: 0 | P40: 0 | Q40: 0 | R40: 0 | S40: 0 | T40: 1 | U40: 1 | V40: 0 | W40: 0 | X40: 0 | Y40: 0 | Z40: 0 | AL40: College graduate | AM40: Yes | AN40: Yes | AO40: No | AP40: Yes | AQ40: Maybe | AR40: Disabled, not able to work | AS40: Female | AT40: 0 | AU40: 0 | AV40: 0 | AW40: 1 | AX40: 0 | AY40: 58_76
...

Sheet Analysis_Female
B1: Wearable device usage by reason_Apps (social media, news, etc.) | C1: Wearable device usage by reason_Fitness and workout monitoring (heart rate, step tracking, jogging, etc.) | D1: Wearable device usage by reason_Sleep monitoring (sleep duration, sleep quality, etc.) | E1: Wearable device usage by reason_Health tracking (blood oxygen, heart rhythm, women's health such as ovulation tracking, etc.) | F1: Wearable device usage by reason_Phone calls, emails, texting | G1: Wearable device usage by reason_Music, audiobooks, or podcasts | H1: Wearable device usage by reason_Navigation (GPS) | I1: Wearable device usage by reason_Wear for fashion
B3: Secondary reason | C3: Main reason | D3: Not a reason | E3: Secondary reason | F3: Main reason | G3: Not a reason | H3: Not a reason | I3: Not a reason
B4: Not a reason | C4: Main reason | D4: Secondary reason | E4: Secondary reason | F4: Secondary reason | G4: Secondary reason | H4: Secondary reason | I4: Secondary reason
B5: Not applicable to my device(s) | C5: Main reason | D5: Secondary reason | E5: Main reason | F5: Not a reason | G5: Not applicable to my device(s) | H5: Not applicable to my device(s) | I5: Not a reason
B7: Not a reason | C7: Main reason | D7: Secondary reason | E7: Not a reason | F7: Not a reason | G7: Not a reason | H7: Not applicable to my device(s) | I7: Not a reason
B10: Secondary reason | C10: Secondary reason | D10: Not applicable to my device(s) | E10: Not a reason | F10: Main reason | G10: Not applicable to my device(s) | H10: Secondary reason | I10: Secondary reason
B11: Not a reason | C11: Main reason | D11: Secondary reason | E11: Secondary reason | F11: Not a reason | G11: Not a reason | H11: Secondary reason | I11: Not a reason
B12: Not applicable to my device(s) | C12: Main reason | D12: Secondary reason | E12: Secondary reason | F12: Not applicable to my device(s) | G12: Not applicable to my device(s) | H12: Not a reason | I12: Not a reason
B13: Secondary reason | C13: Secondary reason | D13: Not a reason | E13: Secondary reason | F13: Main reason | G13: Secondary reason | H13: Secondary reason | I13: Not a reason
B14: Secondary reason | C14: Main reason | D14: Not a reason | E14: Main reason | F14: Main reason | G14: Secondary reason | H14: Main reason | I14: Secondary reason
B15: Not applicable to my device(s) | C15: Main reason | D15: Main reason | E15: Not a reason | F15: Secondary reason | G15: Not applicable to my device(s) | H15: Not applicable to my device(s) | I15: Not a reason
B18: Not a reason | C18: Secondary reason | D18: Main reason | E18: Secondary reason | F18: Not a reason | G18: Not a reason | H18: Not a reason | I18: Not a reason
... B872: Not a reason | C872: Main reason | D872: Secondary reason | E872: Secondary reason | F872: Not a reason | G872: Not a reason | H872: Not a reason | I872: Not a reason
A873: Wearable device usage by reason_
B874: Apps (social media, news, etc.) | C874: Fitness and workout monitoring (heart rate, step tracking, jogging, etc.) | D874: Sleep monitoring (sleep duration, sleep quality, etc.) | E874: Health tracking (blood oxygen, heart rhythm, women's health such as ovulation tracking, etc.) | F874: Phone calls, emails, texting | G874: Music, audiobooks, or podcasts | H874: Navigation (GPS) | I874: Wear for fashion
A875: Main Reason | B875: =COUNTIF(B2:B872, "Main reason") -> 46 | C875: =COUNTIF(C2:C872, "Main reason") -> 358 | D875: =COUNTIF(D2:D872, "Main reason") -> 69 | E875: =COUNTIF(E2:E872, "Main reason") -> 150 | F875: =COUNTIF(F2:F872, "Main reason") -> 196 | G875: =COUNTIF(G2:G872, "Main reason") -> 30 | H875: =COUNTIF(H2:H872, "Main reason") -> 49 | I875: =COUNTIF(I2:I872, "Main reason") -> 28
A876: Secondary Reason | B876: =COUNTIF(B2:B872, "Secondary reason") -> 97 | C876: =COUNTIF(C2:C872, "Secondary reason") -> 125 | D876: =COUNTIF(D2:D872, "Secondary reason") -> 187 | E876: =COUNTIF(E2:E872, "Secondary reason") -> 185 | F876: =COUNTIF(F2:F872, "Secondary reason") -> 142 | G876: =COUNTIF(G2:G872, "Secondary reason") -> 104 | H876: =COUNTIF(H2:H872, "Secondary reason") -> 108 | I876: =COUNTIF(I2:I872, "Secondary reason") -> 74
A877: Not a Reason | B877: =COUNTIF(B2:B872, "Not a reason") -> 293 | C877: =COUNTIF(C2:C872, "Not a reason") -> 44 | D877: =COUNTIF(D2:D872, "Not a reason") -> 232 | E877: =COUNTIF(E2:E872, "Not a reason") -> 140 | F877: =COUNTIF(F2:F872, "Not a reason") -> 144 | G877: =COUNTIF(G2:G872, "Not a reason") -> 285 | H877: =COUNTIF(H2:H872, "Not a reason") -> 266 | I877: =COUNTIF(I2:I872, "Not a reason") -> 378
B880: Main Reason | C880: Secondary Reason | D880: Not a Reason | F880: Total Listed As Reason
A881: Apps (social media, news, etc.) | B881: 46 | C881: 97 | D881: 293 | F881: =sum(B881:C881) -> 143 | G881: 6
A882: Fitness and workout monitoring (heart rate, step tracking, jogging, etc.) | B882: 358 | C882: 125 | D882: 44 | F882: =sum(B882:C882) -> 483 | G882: 1
A883: Sleep monitoring (sleep duration, sleep quality, etc.) | B883: 69 | C883: 187 | D883: 232 | F883: =sum(B883:C883) -> 256 | G883: 4
A884: Health tracking (blood oxygen, heart rhythm, women's health such as ovulation tracking, etc.) | B884: 150 | C884: 185 | D884: 140 | F884: =sum(B884:C884) -> 335 | G884: 3
A885: Phone calls, emails, texting | B885: 196 | C885: 142 | D885: 144 | F885: =sum(B885:C885) -> 338 | G885: 2
A886: Music, audiobooks, or podcasts | B886: 30 | C886: 104 | D886: 285 | F886: =sum(B886:C886) -> 134 | G886: 7
A887: Navigation (GPS) | B887: 49 | C887: 108 | D887: 266 | F887: =sum(B887:C887) -> 157 | G887: 5
A888: Wear for fashion | B888: 28 | C888: 74 | D888: 378 | F888: =sum(B888:C888) -> 102 | G888: 8

Sheet Analysis_Whole
A1: I want one, I just don't have one yet | B1: =countif(Clean!R2:R1369, 1) -> 58
A2: No particular reason | B2: =countif(Clean!S2:S1369, 1) -> 125
A3: Too expensive | B3: =countif(Clean!T2:T1369, 1) -> 178
A4: Too hard to read | B4: =countif(Clean!U2:U1369, 1) -> 17
A5: Don't trust that they work correctly | B5: =countif(Clean!V2:V1369, 1) -> 38
A6: Don't know enough about them | B6: =countif(Clean!W2:W1369, 1) -> 54
A7: Not interested in tracking | B7: =countif(Clean!X2:X1369, 1) -> 127
A8: Privacy reasons | B8: =countif(Clean!Y2:Y1369, 1) -> 68
A9: Reasons fSome other reason not listed (please provide) | B9: =countif(Clean!Z2:Z1369, 1) -> 85
J21: Wearable device usage by reason
K22: Main Reason | L22: Secondary Reason | M22: Not a Reason
A23: Wearable device usage by reason_Apps (social media, news, etc.) | B23: Wearable device usage by reason_Fitness and workout monitoring (heart rate, step tracking, jogging, etc.) | C23: Wearable device usage by reason_Sleep monitoring (sleep duration, sleep quality, etc.) | D23: Wearable device usage by reason_Health tracking (blood oxygen, heart rhythm, women's health such as ovulation tracking, etc.) | E23: Wearable device usage by reason_Phone calls, emails, texting | F23: Wearable device usage by reason_Music, audiobooks, or podcasts | G23: Wearable device usage by reason_Navigation (GPS) | H23: Wearable device usage by reason_Wear for fashion | J23: Apps (social media, news, etc.) | K23: =COUNTIF(A24:A1391, "Main reason") -> 75 | L23: =COUNTIF(A24:A1391, "Secondary reason") -> 157 | M23: =COUNTIF(A24:A1391, "Not a reason") -> 430
J24: Fitness and workout monitoring (heart rate, step tracking, jogging, etc.) | K24: =COUNTIF(B24:B1391, "Main reason") -> 522 | L24: =COUNTIF(B24:B1391, "Secondary reason") -> 188 | M24: =COUNTIF(B24:B1391, "Not a reason") -> 75
A25: Secondary reason | B25: Main reason | C25: Not a reason | D25: Secondary reason | E25: Main reason | F25: Not a reason | G25: Not a reason | H25: Not a reason | J25: Sleep monitoring (sleep duration, sleep quality, etc.) | K25: =COUNTIF(C24:C1391, "Main reason") -> 126 | L25: =COUNTIF(C24:C1391, "Secondary reason") -> 265 | M25: =COUNTIF(C24:C1391, "Not a reason") -> 338
A26: Not a reason | B26: Main reason | C26: Secondary reason | D26: Secondary reason | E26: Main reason | F26: Not a reason | G26: Not applicable to my device(s) | H26: Secondary reason | J26: Health tracking (blood oxygen, heart rhythm, women's health such as ovulation tracking, etc.) | K26: =COUNTIF(D24:D1391, "Main reason") -> 228 | L26: =COUNTIF(D24:D1391, "Secondary reason") -> 272 | M26: =COUNTIF(D24:D1391, "Not a reason") -> 210
J27: Phone calls, emails, texting | K27: =COUNTIF(E24:E1391, "Main reason") -> 291 | L27: =COUNTIF(E24:E1391, "Secondary reason") -> 229 | M27: =COUNTIF(E24:E1391, "Not a reason") -> 200
A28: Not a reason | B28: Main reason | C28: Secondary reason | D28: Secondary reason | E28: Secondary reason | F28: Secondary reason | G28: Secondary reason | H28: Secondary reason | J28: Music, audiobooks, or podcasts | K28: =COUNTIF(F24:F1391, "Main reason") -> 50 | L28: =COUNTIF(F24:F1391, "Secondary reason") -> 161 | M28: =COUNTIF(F24:F1391, "Not a reason") -> 433
A29: Not applicable to my device(s) | B29: Main reason | C29: Secondary reason | D29: Main reason | E29: Not a reason | F29: Not applicable to my device(s) | G29: Not applicable to my device(s) | H29: Not a reason | J29: Navigation (GPS) | K29: =COUNTIF(G24:G1391, "Main reason") -> 72 | L29: =COUNTIF(G24:G1391, "Secondary reason") -> 187 | M29: =COUNTIF(G24:G1391, "Not a reason") -> 385
